Workbook

Sheet Bảng theo dõi
A1: ID | B1: Sprint | C1: Ngày | D1: Module | E1: Tính năng | F1: Phụ thuộc | G1: Giờ | H1: Trạng thái | I1: Điều kiện hoàn thành (DoD) | J1: Ghi chú
A2: T01 | B2: S1 · 18-20/09 | C2: 18-20/09 | D2: Người | E2: Đăng ký DoraHacks + nộp email tài khoản CMC | F2: — | G2: 0.5 | H2: Chưa làm | I2: Email tài khoản CMC đã nộp | J2: Chặn toàn bộ phần cần key
A3: T02 | B3: S1 · 18-20/09 | C3: 18-20/09 | D3: M1 | E3: Khung dự án + nạp cấu hình từ .env | F3: — | G3: 1 | H3: Chưa làm | I3: python cli.py --help chạy được
A4: T03 | B4: S1 · 18-20/09 | C4: 18-20/09 | D4: M1 | E4: Logging có cấu trúc | F4: T02 | G4: 1 | H4: Chưa làm | I4: Log đọc được, có mức và timestamp
A5: T04 | B5: S1 · 18-20/09 | C5: 18-20/09 | D5: M1 | E5: Phân loại lỗi: Auth / RateLimit / PartialData | F5: T03 | G5: 1 | H5: Chưa làm | I5: Mỗi loại lỗi có lớp riêng
A6: T05 | B6: S1 · 18-20/09 | C6: 18-20/09 | D6: M2 | E6: Tầng HTTP hai chế độ keyless / có key | F6: T02 | G6: 2 | H6: Chưa làm | I6: Gọi được cả hai chế độ
A7: T06 | B7: S1 · 18-20/09 | C7: 18-20/09 | D7: M2 | E7: Khai báo endpoint + động từ GET/POST một chỗ | F7: T10 | G7: 1 | H7: Chưa làm | I7: endpoints.py là nguồn duy nhất
A8: T07 | B8: S1 · 18-20/09 | C8: 18-20/09 | D8: M2 | E8: Cache TTL 60 giây | F8: T05 | G8: 1 | H8: Chưa làm | I8: Lần gọi thứ hai trong 60s là cache hit
A9: T08 | B9: S1 · 18-20/09 | C9: 18-20/09 | D9: M2 | E9: Backoff khi gặp 429 + retry | F9: T05 | G9: 1 | H9: Chưa làm | I9: Test mock 429 thành công sau retry
A10: T09 | B10: S1 · 18-20/09 | C10: 18-20/09 | D10: M2 | E10: Nhật ký lời gọi: endpoint, tham số, status, ms, cache | F10: T05 | G10: 1 | H10: Chưa làm | I10: Mọi lời gọi đều có dòng log
A11: T10 | B11: S1 · 18-20/09 | C11: 18-20/09 | D11: M3 | E11: Đọc tài liệu 14 endpoint: TÊN TRƯỜNG và động từ | F11: — | G11: 3 | H11: Chưa làm | I11: Có bảng tên trường cho từng endpoint | J11: Mốc rủi ro cao nhất của sprint
A12: T11 | B12: S1 · 18-20/09 | C12: 18-20/09 | D12: M11 | E12: Khảo sát 5-10 token / 2 chain, chụp response thật | F12: T05, T10 | G12: 4 | H12: Chưa làm | I12: docs/evidence có response kèm timestamp
A13: T12 | B13: S1 · 18-20/09 | C13: 18-20/09 | D13: M11 | E13: Báo cáo khảo sát dữ liệu | F13: T11 | G13: 2 | H13: Chưa làm | I13: Trả lời đủ 4 câu hỏi của cổng 1
A14: T13 | B14: S2 · 21-23/09 | C14: 21-23/09 | D14: M3 | E14: dataclass models nội bộ | F14: T10 | G14: 2 | H14: Chưa làm | I14: Có model cho 6 loại dữ liệu
A15: T14 | B15: S2 · 21-23/09 | C15: 21-23/09 | D15: M3 | E15: Chuẩn hoá JSON sang model, phân biệt thiếu trường với 0 | F15: T13 | G15: 3 | H15: Chưa làm | I15: Không crash khi thiếu trường
A16: T15 | B16: S2 · 21-23/09 | C16: 21-23/09 | D16: M4 | E16: Resolver: search + chọn khi mơ hồ | F16: T05, T14 | G16: 2 | H16: Chưa làm | I16: Nhiều kết quả thì in danh sách, không tự chọn
A17: T16 | B17: S2 · 21-23/09 | C17: 21-23/09 | D17: M4 | E17: Collector gom song song + lỗi từng phần + độ phủ | F17: T15 | G17: 3 | H17: Chưa làm | I17: Tính được % độ phủ dữ liệu
A18: T17 | B18: S2 · 21-23/09 | C18: 21-23/09 | D18: M5 | E18: Chiều A — xu hướng thanh khoản | F18: T14 | G18: 3 | H18: Chưa làm | I18: Test pass trên fixture
A19: T18 | B19: S2 · 21-23/09 | C19: 21-23/09 | D19: M5 | E19: Chiều B — cô đặc holder | F19: T14 | G19: 2 | H19: Chưa làm | I19: Test pass trên fixture
A20: T19 | B20: S2 · 21-23/09 | C20: 21-23/09 | D20: M5 | E20: Chiều C — rủi ro hợp đồng | F20: T14 | G20: 2 | H20: Chưa làm | I20: Test pass trên fixture
A21: T20 | B21: S2 · 21-23/09 | C21: 21-23/09 | D21: M7 | E21: Gộp điểm + trọng số + độ phủ | F21: T17, T18, T19 | G21: 2 | H21: Chưa làm | I21: 5 chiều cộng đúng 100 điểm
A22: T21 | B22: S2 · 21-23/09 | C22: 21-23/09 | D22: M7 | E22: Xếp mức kết luận + chọn và xếp 3 lý do | F22: T20 | G22: 2 | H22: Chưa làm | I22: 3 lý do đều kèm số
A23: T22 | B23: S2 · 21-23/09 | C23: 21-23/09 | D23: M9 | E23: Bản in terminal | F23: T21 | G23: 3 | H23: Chưa làm | I23: Có khối endpoint đã gọi
... A25: T24 | B25: S2 · 21-23/09 | C25: 21-23/09 | D25: M12 | E25: Test cho chiều A/B/C | F25: T17, T18, T19 | G25: 3 | H25: Chưa làm | I25: pytest xanh, không cần mạng
A26: T25 | B26: S3 · 24-26/09 | C26: 24-26/09 | D26: M6 | E26: Đọc tài liệu holders/trend + tag_count, xác định nhãn | F26: Key Startup | G26: 2 | H26: Chưa làm | I26: Biết chắc CMC có những nhãn nào | J26: Quyết định chiều E có khả thi
A27: T26 | B27: S3 · 24-26/09 | C27: 24-26/09 | D27: M6 | E27: Phân tích phân bố holder theo nhãn | F27: T25 | G27: 3 | H27: Chưa làm | I27: Ra được phân bố theo nhãn
A28: T27 | B28: S3 · 24-26/09 | C28: 24-26/09 | D28: M6 | E28: Chiều E — dòng ròng và hướng đi (−15 đến +15) | F28: T26 | G28: 3 | H28: Chưa làm | I28: Chiều E âm trên ít nhất 1 token
A29: T28 | B29: S3 · 24-26/09 | C29: 24-26/09 | D29: M6 | E29: Chiều D — lớp đòn bẩy phái sinh | F29: Key Startup | G29: 2 | H29: Chưa làm | I29: Thiếu dữ liệu thì ghi không áp dụng
A30: T29 | B30: S3 · 24-26/09 | C30: 24-26/09 | D30: M8 | E30: Lưu watchlist, có phiên bản hoá file | F30: T21 | G30: 1.5 | H30: Chưa làm | I30: Ghi và đọc lại đúng
A31: T30 | B31: S3 · 24-26/09 | C31: 24-26/09 | D31: M8 | E31: Tính và in delta so với lần quét trước | F31: T29 | G31: 1.5 | H31: Chưa làm | I31: Delta đúng trên 2 lần chạy
A32: T31 | B32: S3 · 24-26/09 | C32: 24-26/09 | D32: M11 | E32: Chế độ --offline + fixtures | F32: T05, T16 | G32: 2 | H32: Chưa làm | I32: Ngắt mạng vẫn ra kết luận
A33: T32 | B33: S3 · 24-26/09 | C33: 24-26/09 | D33: M11 | E33: Dọn docs/evidence | F33: T11 | G33: 1 | H33: Chưa làm | I33: Có response thật kèm timestamp
A34: T33 | B34: S3 · 24-26/09 | C34: 24-26/09 | D34: M12 | E34: Test suite hoàn thiện | F34: T27, T21 | G34: 3 | H34: Chưa làm | I34: Bao phủ cả 5 chiều
A35: T34 | B35: S3 · 24-26/09 | C35: 24-26/09 | D35: M9 | E35: Đầu ra JSON | F35: T21 | G35: 1 | H35: Chưa làm | I35: JSON hợp lệ, parse được | J35: Ứng viên cắt số 3
A36: T35 | B36: S4 · 27-28/09 | C36: 27-28/09 | D36: M14 | E36: Design tokens + khung trang | F36: T22 | G36: 2 | H36: Chưa làm | I36: Tokens khớp file thiết kế
A37: T36 | B37: S4 · 27-28/09 | C37: 27-28/09 | D37: M14 | E37: Màn Quét + ô tìm kiếm + gợi ý | F37: T35 | G37: 3 | H37: Chưa làm | I37: Gõ ra gợi ý sau 300ms
A38: T37 | B38: S4 · 27-28/09 | C38: 27-28/09 | D38: M14 | E38: Màn Kết quả + 5 thanh chiều + khối dòng tiền | F38: T35, T21 | G38: 4 | H38: Chưa làm | I38: Hiện đúng ví dụ trong bản thiết kế
A39: T38 | B39: S4 · 27-28/09 | C39: 27-28/09 | D39: M14 | E39: Màn Theo dõi + delta | F39: T30 | G39: 2 | H39: Chưa làm | I39: Bảng có cột thay đổi
A40: T39 | B40: S4 · 27-28/09 | C40: 27-28/09 | D40: M14 | E40: Cài đặt + 8 trạng thái lỗi | F40: T35 | G40: 2 | H40: Chưa làm | I40: Đủ 8 trạng thái lỗi
A41: T40 | B41: S4 · 27-28/09 | C41: 27-28/09 | D41: M14 | E41: Responsive + dark/light + accessibility | F41: T36, T37, T38, T39 | G41: 2 | H41: Chưa làm | I41: Dùng được chỉ bằng bàn phím
...

Sheet Theo sprint
A1: Sprint | B1: Ngày | C1: Tổng giờ | D1: Giờ đã xong | E1: Còn lại | F1: % xong | G1: Số tính năng | H1: Đã xong | I1: Mục tiêu | J1: Cổng kiểm soát
A2: S1 · 18-20/09 | B2: 18-20/09 | C2: =SUMIFS('Bảng theo dõi'!$G$2:$G$50,'Bảng theo dõi'!$B$2:$B$50,$A2) -> 18.5 | D2: =SUMIFS('Bảng theo dõi'!$G$2:$G$50,'Bảng theo dõi'!$B$2:$B$50,$A2,'Bảng theo dõi'!$H$2:$H$50,"Xong") -> 0 | E2: =C2-D2 -> 18.5 | F2: =IFERROR(D2/C2,0) -> 0 | G2: =COUNTIFS('Bảng theo dõi'!$B$2:$B$50,$A2) -> 12 | H2: =COUNTIFS('Bảng theo dõi'!$B$2:$B$50,$A2,'Bảng theo dõi'!$H$2:$H$50,"Xong") -> 0 | I2: Chạm được dữ liệu thật | J2: Sáng T2 21/09
A3: S2 · 21-23/09 | B3: 21-23/09 | C3: =SUMIFS('Bảng theo dõi'!$G$2:$G$50,'Bảng theo dõi'!$B$2:$B$50,$A3) -> 30 | D3: =SUMIFS('Bảng theo dõi'!$G$2:$G$50,'Bảng theo dõi'!$B$2:$B$50,$A3,'Bảng theo dõi'!$H$2:$H$50,"Xong") -> 0 | E3: =C3-D3 -> 30 | F3: =IFERROR(D3/C3,0) -> 0 | G3: =COUNTIFS('Bảng theo dõi'!$B$2:$B$50,$A3) -> 12 | H3: =COUNTIFS('Bảng theo dõi'!$B$2:$B$50,$A3,'Bảng theo dõi'!$H$2:$H$50,"Xong") -> 0 | I3: Walking skeleton: chạy end-to-end | J3: Tối T4 23/09
A4: S3 · 24-26/09 | B4: 24-26/09 | C4: =SUMIFS('Bảng theo dõi'!$G$2:$G$50,'Bảng theo dõi'!$B$2:$B$50,$A4) -> 20 | D4: =SUMIFS('Bảng theo dõi'!$G$2:$G$50,'Bảng theo dõi'!$B$2:$B$50,$A4,'Bảng theo dõi'!$H$2:$H$50,"Xong") -> 0 | E4: =C4-D4 -> 20 | F4: =IFERROR(D4/C4,0) -> 0 | G4: =COUNTIFS('Bảng theo dõi'!$B$2:$B$50,$A4) -> 10 | H4: =COUNTIFS('Bảng theo dõi'!$B$2:$B$50,$A4,'Bảng theo dõi'!$H$2:$H$50,"Xong") -> 0 | I4: Dòng tiền cá mập + delta + offline | J4: Sáng T2 28/09
A5: S4 · 27-28/09 | B5: 27-28/09 | C5: =SUMIFS('Bảng theo dõi'!$G$2:$G$50,'Bảng theo dõi'!$B$2:$B$50,$A5) -> 20.5 | D5: =SUMIFS('Bảng theo dõi'!$G$2:$G$50,'Bảng theo dõi'!$B$2:$B$50,$A5,'Bảng theo dõi'!$H$2:$H$50,"Xong") -> 0 | E5: =C5-D5 -> 20.5 | F5: =IFERROR(D5/C5,0) -> 0 | G5: =COUNTIFS('Bảng theo dõi'!$B$2:$B$50,$A5) -> 10 | H5: =COUNTIFS('Bảng theo dõi'!$B$2:$B$50,$A5,'Bảng theo dõi'!$H$2:$H$50,"Xong") -> 0 | I5: Đóng gói: README + video | J5: Tối T2 28/09
A6: S5 · 29/09 | B6: 29/09 | C6: =SUMIFS('Bảng theo dõi'!$G$2:$G$50,'Bảng theo dõi'!$B$2:$B$50,$A6) -> 2.5 | D6: =SUMIFS('Bảng theo dõi'!$G$2:$G$50,'Bảng theo dõi'!$B$2:$B$50,$A6,'Bảng theo dõi'!$H$2:$H$50,"Xong") -> 0 | E6: =C6-D6 -> 2.5 | F6: =IFERROR(D6/C6,0) -> 0 | G6: =COUNTIFS('Bảng theo dõi'!$B$2:$B$50,$A6) -> 4 | H6: =COUNTIFS('Bảng theo dõi'!$B$2:$B$50,$A6,'Bảng theo dõi'!$H$2:$H$50,"Xong") -> 0 | I6: Nộp bài | J6: Link bài nộp + post X
A7: Đệm · 30/09 | B7: 30/09 | C7: =SUMIFS('Bảng theo dõi'!$G$2:$G$50,'Bảng theo dõi'!$B$2:$B$50,$A7) -> 6 | D7: =SUMIFS('Bảng theo dõi'!$G$2:$G$50,'Bảng theo dõi'!$B$2:$B$50,$A7,'Bảng theo dõi'!$H$2:$H$50,"Xong") -> 0 | E7: =C7-D7 -> 6 | F7: =IFERROR(D7/C7,0) -> 0 | G7: =COUNTIFS('Bảng theo dõi'!$B$2:$B$50,$A7) -> 1 | H7: =COUNTIFS('Bảng theo dõi'!$B$2:$B$50,$A7,'Bảng theo dõi'!$H$2:$H$50,"Xong") -> 0 | I7: Chỉ sửa lỗi nhỏ | J7: —
A8: TỔNG | C8: =SUM(C2:C7) -> 97.5 | D8: =SUM(D2:D7) -> 0 | E8: =SUM(E2:E7) -> 97.5 | F8: =IFERROR(D8/C8,0) -> 0 | G8: =SUM(G2:G7) -> 49 | H8: =SUM(H2:H7) -> 0

Sheet Cổng kiểm soát
A1: Cổng | B1: Ngày | C1: Ai duyệt | D1: Tiêu chí đạt | E1: Phương án nếu KHÔNG đạt
A2: Cổng 1 — sau S1 | B2: Sáng T2 21/09 | C2: Người | D2: Biết chắc 4 điều: (1) động từ HTTP từng endpoint, (2) tên trường thật, (3) holders/trend/list và tag_count trả gì, (4) chain nào có liquidity-change tốt | E2: Chuyển ngay sang phương án B ở sheet Rủi ro. Không bước vào S2 khi còn mơ hồ về tên trường.
A3: Cổng 2 — sau S2 | B3: Tối T4 23/09 | C3: Người | D3: Chạy cli.py trên token thật ra kết luận có 3 lý do kèm số; có ít nhất 1 token cho điểm thấp | E3: Cắt chiều B xuống mức tối giản, dồn thời gian cho đường găng. Không cắt chiều A.
A4: Cổng 3 — sau S3 | B4: Sáng T2 28/09 | C4: Người | D4: Chiều E cho điểm âm trên ít nhất 1 token; --offline chạy khi ngắt mạng; delta in đúng | E4: Key chưa về thì rút chiều E xuống holders/list + detail và ghi rõ. Vẫn không đủ thì bỏ chiều E, dồn trọng số, ghi vào roadmap.
A5: Cổng 4 — sau S4 | B5: Tối T2 28/09 | C5: Người | D5: Video đã quay và upload; README đủ 7 mục; repo sạch key | E5: HTML lỗi thì quay video trên bản in terminal + ảnh chụp. Không để HTML chặn việc nộp.
A6: Cổng cuối | B6: 29/09 | C6: Người | D6: Có link bài nộp trên DoraHacks và link bài post X kèm #BuildwithCMC | E6: Nộp trước deadline ít nhất 36 giờ. Ngày 30/09 chỉ sửa lỗi nhỏ.

Sheet Rủi ro & dự phòng
A1: Thứ tự | B1: Tình huống | C1: Phương án B | D1: Ảnh hưởng tới bài nộp
A2: Bắt buộc | B2: liquidity-change/list không có dữ liệu tốt | C2: Dùng token/pools làm proxy: số pool giảm và thanh khoản dồn vào 1 pool | D2: Mất tín hiệu mạnh nhất, vẫn dùng được dữ liệu DEX
A3: Bắt buộc | B3: Nhóm Holder không đủ dữ liệu | C3: Rút chiều E xuống holders/list + holders/detail, ghi rõ là suy luận | D3: Mất nhãn chính thức, giữ được tính năng
A4: Bắt buộc | B4: Key Startup chưa về trước 26/09 | C4: Chạy toàn bộ trên keyless; chiều D và E thành không áp dụng | D4: Độ phủ giảm còn 3/5, nhưng vẫn trung thực
A5: Cắt 1 | B5: Tụt tiến độ | C5: Cắt chiều D — đòn bẩy phái sinh | D5: Ít ảnh hưởng, chỉ 10 điểm
A6: Cắt 2 | B6: Tụt tiến độ | C6: Cắt báo cáo HTML | D6: Video quay trên bản in terminal
A7: Cắt 3 | B7: Tụt tiến độ | C7: Cắt đầu ra JSON | D7: Không ai chấm phần này
A8: Cắt 4 | B8: Tụt tiến độ | C8: Cắt tín hiệu phụ của chiều B | D8: Giữ tín hiệu chính là đủ
A9: Cắt 5 | B9: Tụt tiến độ | C9: Cắt chiều E | D9: Đau, nhưng sản phẩm vẫn còn giá trị
A10: KHÔNG CẮT | B10: Bốn thứ không bao giờ cắt | C10: Chiều A · delta watchlist · chế độ --offline · README + video | D10: Đây là bốn thứ giám khảo chấm trực tiếp

Sheet Hướng dẫn
A1: Hướng dẫn sử dụng bảng theo dõi
A3: 1. Cột Giờ và Điều kiện hoàn thành: xem để biết khối lượng, không cần sửa.
A4: 2. Cột Trạng thái (nền vàng): bấm chọn Chưa làm / Đang làm / Xong / Bỏ / Chặn.
A5: 3. Cột Ghi chú (nền vàng): ghi lý do trễ, quyết định cắt, hoặc việc phát sinh.
A6: 4. Sheet Theo sprint tự động cộng giờ và tính % xong từ cột Trạng thái — không sửa tay.
A7: 5. Sheet Cổng kiểm soát: 5 mốc cần người duyệt. Không vượt cổng khi chưa quyết định.
A8: 6. Sheet Rủi ro & dự phòng: phương án B đã viết sẵn, không phải nghĩ lúc hoảng.
A10: Giả định và nguồn số liệu:
A11: · Giờ là giờ công của agent AI, không phải giờ làm việc của người.
A12: · Ước lượng lập ở mức tính năng (không phải mức module) nên cao hơn con số trong kế hoạch dự án ban đầu.
A13: · Đã bao gồm 15 giờ của module M14 — Web UI, và 6 giờ đệm ngày 30/09.
A14: · Deadline nộp: 30/09/2026 23:59 UTC = 06:59 sáng 01/10 giờ Việt Nam.
... A17: Tổng công việc: 92 giờ · Đệm: 6 giờ · Tổng: 98 giờ trên 11 ngày làm việc.
